sample.csv
timestampNano,keySymbol,lastPrice,lastQty,ask1p,ask1q,ask2p,ask2q,ask3p,ask3q,ask4p,ask4q,ask5p,ask5q,bid1p,bid1q,bid2p,bid2q,bid3p,bid3q,bid4p,bid4q,bid5p,bid5q
2017-02-24 08:00:00,SC,0.0,0,192.4,80,192.45,55,192.5,71,192.55,81,192.6,49,192.35,6,192.3,34,192.25,31,192.2,77,192.15,63
2017-02-24 08:00:00,SC,0.0,0,192.4,80,192.45,55,192.5,71,192.55,81,192.6,49,192.35,7,192.3,34,192.25,31,192.2,77,192.15,63
2017-02-24 08:00:00,SC,0.0,0,192.4,80,192.45,55,192.5,71,192.55,81,192.6,49,192.35,8,192.3,34,192.25,31,192.2,77,192.15,63
2017-02-24 08:00:00,SC,0.0,0,192.4,80,192.45,55,192.5,71,192.55,81,192.6,49,192.35,9,192.3,34,192.25,31,192.2,77,192.15,63
2017-02-24 08:00:00,SC,0.0,0,192.4,80,192.45,55,192.5,71,192.55,81,192.6,49,192.35,10,192.3,34,192.25,31,192.2,77,192.15,63
2017-02-24 08:00:00,SC,192.35,1,192.4,80,192.45,55,192.5,71,192.55,81,192.6,49,192.35,9,192.3,34,192.25,31,192.2,77,192.15,63
2017-02-24 08:00:00,SC,0.0,0,192.4,80,192.45,55,192.5,71,192.55,81,192.6,49,192.35,9,192.3,35,192.25,31,192.2,77,192.15,63
2017-02-24 08:00:00,SC,192.35,1,192.4,80,192.45,55,192.5,71,192.55,81,192.6,49,192.35,8,192.3,35,192.25,31,192.2,77,192.15,63
2017-02-24 08:00:00,SC,192.35,1,192.4,80,192.45,55,192.5,71,192.55,81,192.6,49,192.35,7,192.3,35,192.25,31,192.2,77,192.15,63
2017-02-24 08:00:00,SC,192.35,1,192.4,80,192.45,55,192.5,71,192.55,81,192.6,49,192.35,6,192.3,35,192.25,31,192.2,77,192.15,63
2017-02-24 08:00:00,SC,192.35,1,192.4,80,192.45,55,192.5,71,192.55,81,192.6,49,192.35,5,192.3,35,192.25,31,192.2,77,192.15,63
2017-02-24 08:00:00,SC,192.35,1,192.4,80,192.45,55,192.5,71,192.55,81,192.6,49,192.35,4,192.3,35,192.25,31,192.2,77,192.15,63
2017-02-24 08:00:00,SC,192.35,1,192.4,80,192.45,55,192.5,71,192.55,81,192.6,49,192.35,3,192.3,35,192.25,31,192.2,77,192.15,63
2017-02-24 08:00:00,SC,192.35,1,192.4,80,192.45,55,192.5,71,192.55,81,192.6,49,192.35,2,192.3,35,192.25,31,192.2,77,192.15,63
2017-02-24 08:00:00,SC,192.35,1,192.4,80,192.45,55,192.5,71,192.55,81,192.6,49,192.35,1,192.3,35,192.25,31,192.2,77,192.15,63
2017-02-24 08:00:00,SC,192.35,1,192.4,80,192.45,55,192.5,71,192.55,81,192.6,49,192.3,35,192.25,31,192.2,77,192.15,63,192.1,102
2017-02-24 08:00:00,SC,0.0,0,192.35,3,192.4,80,192.45,55,192.5,71,192.55,81,192.3,35,192.25,31,192.2,77,192.15,63,192.1,102
2017-02-24 08:00:00,SC,0.0,0,192.35,7,192.4,80,192.45,55,192.5,71,192.55,81,192.3,35,192.25,31,192.2,77,192.15,63,192.1,102
2017-02-24 08:00:00,SC,0.0,0,192.35,7,192.4,80,192.45,55,192.5,71,192.55,81,192.3,33,192.25,31,192.2,77,192.15,63,192.1,102
2017-02-24 08:00:00,SC,0.0,0,192.35,7,192.4,79,192.45,55,192.5,71,192.55,81,192.3,33,192.25,31,192.2,77,192.15,63,192.1,102
2017-02-24 08:00:00,SC,0.0,0,192.35,8,192.4,79,192.45,55,192.5,71,192.55,81,192.3,33,192.25,31,192.2,77,192.15,63,192.1,102
2017-02-24 08:00:00,SC,0.0,0,192.35,8,192.4,79,192.45,55,192.5,71,192.55,81,192.3,33,192.25,31,192.2,77,192.15,63,192.1,102
2017-02-24 08:00:00,SC,0.0,0,192.35,8,192.4,79,192.45,55,192.5,71,192.55,81,192.3,33,192.25,31,192.2,77,192.15,63,192.1,102
2017-02-24 08:00:00,SC,0.0,0,192.35,8,192.4,79,192.45,55,192.5,71,192.55,81,192.3,33,192.25,31,192.2,77,192.15,63,192.1,102
2017-02-24 08:00:00,SC,0.0,0,192.35,8,192.4,80,192.45,55,192.5,71,192.55,81,192.3,33,192.25,31,192.2,77,192.15,63,192.1,102
2017-02-24 08:00:00,SC,0.0,0,192.35,8,192.4,80,192.45,55,192.5,71,192.55,81,192.3,33,192.25,31,192.2,77,192.15,63,192.1,102
2017-02-24 08:00:00,SC,0.0,0,192.35,8,192.4,80,192.45,55,192.5,71,192.55,81,192.3,33,192.25,31,192.2,77,192.15,63,192.1,102
2017-02-24 08:00:00,SC,0.0,0,192.35,8,192.4,80,192.45,55,192.5,71,192.55,81,192.3,33,192.25,31,192.2,77,192.15,63,192.1,102
2017-02-24 08:00:00,SC,0.0,0,192.35,8,192.4,80,192.45,55,192.5,71,192.55,81,192.3,38,192.25,31,192.2,77,192.15,63,192.1,102
2017-02-24 08:00:00,SC,0.0,0,192.35,8,192.4,80,192.45,55,192.5,71,192.55,81,192.3,38,192.25,31,192.2,77,192.15,63,192.1,102
2017-02-24 08:00:00,SC,192.35,3,192.35,5,192.4,80,192.45,55,192.5,71,192.55,81,192.3,38,192.25,31,192.2,77,192.15,63,192.1,102
2017-02-24 08:00:00,SC,192.35,1,192.35,4,192.4,80,192.45,55,192.5,71,192.55,81,192.3,38,192.25,31,192.2,77,192.15,63,192.1,102
2017-02-24 08:00:00,SC,0.0,0,192.35,4,192.4,80,192.45,55,192.5,71,192.55,81,192.3,39,192.25,31,192.2,77,192.15,63,192.1,102
2017-02-24 08:00:00,SC,0.0,0,192.35,3,192.4,80,192.45,55,192.5,71,192.55,81,192.3,39,192.25,31,192.2,77,192.15,63,192.1,102
2017-02-24 08:00:00,SC,192.35,3,192.4,80,192.45,55,192.5,71,192.55,81,192.6,49,192.3,39,192.25,31,192.2,77,192.15,63,192.1,102
2017-02-24 08:00:00,SC,192.4,2,192.4,78,192.45,55,192.5,71,192.55,81,192.6,49,192.3,39,192.25,31,192.2,77,192.15,63,192.1,102
2017-02-24 08:00:00,SC,192.4,2,192.4,76,192.45,55,192.5,71,192.55,81,192.6,49,192.3,39,192.25,31,192.2,77,192.15,63,192.1,102
2017-02-24 08:00:00,SC,192.4,1,192.4,75,192.45,55,192.5,71,192.55,81,192.6,49,192.3,39,192.25,31,192.2,77,192.15,63,192.1,102
2017-02-24 08:00:00,SC,192.4,1,192.4,74,192.45,55,192.5,71,192.55,81,192.6,49,192.3,39,192.25,31,192.2,77,192.15,63,192.1,102
2017-02-24 08:00:00,SC,192.4,1,192.4,73,192.45,55,192.5,71,192.55,81,192.6,49,192.3,39,192.25,31,192.2,77,192.15,63,192.1,102
2017-02-24 08:00:00,SC,192.4,1,192.4,72,192.45,55,192.5,71,192.55,81,192.6,49,192.3,39,192.25,31,192.2,77,192.15,63,192.1,102
2017-02-24 08:00:00,SC,192.4,3,192.4,69,192.45,55,192.5,71,192.55,81,192.6,49,192.3,39,192.25,31,192.2,77,192.15,63,192.1,102
2017-02-24 08:00:00,SC,192.4,2,192.4,67,192.45,55,192.5,71,192.55,81,192.6,49,192.3,39,192.25,31,192.2,77,192.15,63,192.1,102
2017-02-24 08:00:00,SC,192.4,1,192.4,66,192.45,55,192.5,71,192.55,81,192.6,49,192.3,39,192.25,31,192.2,77,192.15,63,192.1,102
2017-02-24 08:00:00,SC,192.3,1,192.4,66,192.45,55,192.5,71,192.55,81,192.6,49,192.3,38,192.25,31,192.2,77,192.15,63,192.1,102
2017-02-24 08:00:00,SC,192.3,1,192.4,66,192.45,55,192.5,71,192.55,81,192.6,49,192.3,37,192.25,31,192.2,77,192.15,63,192.1,102
2017-02-24 08:00:00,SC,192.3,1,192.4,66,192.45,55,192.5,71,192.55,81,192.6,49,192.3,36,192.25,31,192.2,77,192.15,63,192.1,102
2017-02-24 08:00:00,SC,192.3,1,192.4,66,192.45,55,192.5,71,192.55,81,192.6,49,192.3,35,192.25,31,192.2,77,192.15,63,192.1,102
2017-02-24 08:00:00,SC,192.3,1,192.4,66,192.45,55,192.5,71,192.55,81,192.6,49,192.3,34,192.25,31,192.2,77,192.15,63,192.1,102
2017-02-24 08:00:00,SC,192.3,1,192.4,66,192.45,55,192.5,71,192.55,81,192.6,49,192.3,33,192.25,31,192.2,77,192.15,63,192.1,102
2017-02-24 08:00:00,SC,192.3,3,192.4,66,192.45,55,192.5,71,192.55,81,192.6,49,192.3,30,192.25,31,192.2,77,192.15,63,192.1,102
2017-02-24 08:00:00,SC,192.3,1,192.4,66,192.45,55,192.5,71,192.55,81,192.6,49,192.3,29,192.25,31,192.2,77,192.15,63,192.1,102
2017-02-24 08:00:00,SC,192.3,3,192.4,66,192.45,55,192.5,71,192.55,81,192.6,49,192.3,26,192.25,31,192.2,77,192.15,63,192.1,102
2017-02-24 08:00:00,SC,192.3,4,192.4,66,192.45,55,192.5,71,192.55,81,192.6,49,192.3,22,192.25,31,192.2,77,192.15,63,192.1,102
2017-02-24 08:00:00,SC,0.0,0,192.4,65,192.45,55,192.5,71,192.55,81,192.6,49,192.3,22,192.25,31,192.2,77,192.15,63,192.1,102
2017-02-24 08:00:00,SC,0.0,0,192.4,65,192.45,55,192.5,71,192.55,81,192.6,49,192.3,21,192.25,31,192.2,77,192.15,63,192.1,102
2017-02-24 08:00:00,SC,0.0,0,192.4,65,192.45,55,192.5,71,192.55,81,192.6,49,192.3,24,192.25,31,192.2,77,192.15,63,192.1,102
2017-02-24 08:00:00,SC,0.0,0,192.4,65,192.45,55,192.5,71,192.55,81,192.6,49,192.35,3,192.3,24,192.25,31,192.2,77,192.15,63
2017-02-24 08:00:00,SC,0.0,0,192.4,65,192.45,55,192.5,71,192.55,81,192.6,49,192.35,3,192.3,24,192.25,33,192.2,77,192.15,63
2017-02-24 08:00:00,SC,0.0,0,192.4,70,192.45,55,192.5,71,192.55,81,192.6,49,192.35,3,192.3,24,192.25,33,192.2,77,192.15,63
2017-02-24 08:00:00,SC,0.0,0,192.4,70,192.45,55,192.5,71,192.55,81,192.6,50,192.35,3,192.3,24,192.25,33,192.2,77,192.15,63
2017-02-24 08:00:00,SC,0.0,0,192.4,70,192.45,55,192.5,71,192.55,81,192.6,50,192.35,3,192.3,24,192.25,33,192.2,77,192.15,63
2017-02-24 08:00:00,SC,0.0,0,192.4,70,192.45,55,192.5,71,192.55,81,192.6,50,192.35,4,192.3,24,192.25,33,192.2,77,192.15,63
